{
 "cells": [
  {
   "cell_type": "code",
   "execution_count": 4,
   "metadata": {},
   "outputs": [],
   "source": [
    "import pandas as pd\n",
    "from sqlalchemy import create_engine\n",
    "import pymongo\n",
    "import dns\n",
    "\n",
    "csv_file = \"crime_and_incarceration_by_state.csv\"\n",
    "crime_and_incarceration_by_state_df = pd.read_csv(csv_file)\n",
    "crime_and_incarceration_by_state_df.head()\n",
    "\n",
    "#rds_connection_string = \"dbUser:dbUserPassword@localhost:5432/etl_project_db\"\n",
    "#engine = create_engine(f'postgresql://{rds_connection_string}')\n",
    "\n",
    "client = pymongo.MongoClient(\"mongodb+srv://dbUser:dbUserPassword@cluster0-sdi7u.gcp.mongodb.net/etl_project?retryWrites=true&w=majority\")\n",
    "db = client.etl_project"
   ]
  },
  {
   "cell_type": "code",
   "execution_count": 6,
   "metadata": {},
   "outputs": [
    {
     "ename": "TypeError",
     "evalue": "'Collection' object is not callable. If you meant to call the 'table_names' method on a 'Database' object it is failing because no such method exists.",
     "output_type": "error",
     "traceback": [
      "\u001b[1;31m---------------------------------------------------------------------------\u001b[0m",
      "\u001b[1;31mTypeError\u001b[0m                                 Traceback (most recent call last)",
      "\u001b[1;32m<ipython-input-6-d0095e6b8f30>\u001b[0m in \u001b[0;36m<module>\u001b[1;34m\u001b[0m\n\u001b[1;32m----> 1\u001b[1;33m \u001b[0mdb\u001b[0m\u001b[1;33m.\u001b[0m\u001b[0mtable_names\u001b[0m\u001b[1;33m(\u001b[0m\u001b[1;33m)\u001b[0m\u001b[1;33m\u001b[0m\u001b[1;33m\u001b[0m\u001b[0m\n\u001b[0m",
      "\u001b[1;32mc:\\users\\fred\\appdata\\local\\programs\\python\\python37-32\\lib\\site-packages\\pymongo\\collection.py\u001b[0m in \u001b[0;36m__call__\u001b[1;34m(self, *args, **kwargs)\u001b[0m\n\u001b[0;32m   3337\u001b[0m                             \u001b[1;34m\"object it is failing because no such method \"\u001b[0m\u001b[1;33m\u001b[0m\u001b[1;33m\u001b[0m\u001b[0m\n\u001b[0;32m   3338\u001b[0m                             \u001b[1;34m\"exists.\"\u001b[0m \u001b[1;33m%\u001b[0m\u001b[1;33m\u001b[0m\u001b[1;33m\u001b[0m\u001b[0m\n\u001b[1;32m-> 3339\u001b[1;33m                             self.__name)\n\u001b[0m\u001b[0;32m   3340\u001b[0m         raise TypeError(\"'Collection' object is not callable. If you meant to \"\n\u001b[0;32m   3341\u001b[0m                         \u001b[1;34m\"call the '%s' method on a 'Collection' object it is \"\u001b[0m\u001b[1;33m\u001b[0m\u001b[1;33m\u001b[0m\u001b[0m\n",
      "\u001b[1;31mTypeError\u001b[0m: 'Collection' object is not callable. If you meant to call the 'table_names' method on a 'Database' object it is failing because no such method exists."
     ]
    }
   ],
   "source": [
    "#engine.table_names()"
   ]
  },
  {
   "cell_type": "code",
   "execution_count": null,
   "metadata": {},
   "outputs": [],
   "source": []
  },
  {
   "cell_type": "code",
   "execution_count": null,
   "metadata": {},
   "outputs": [],
   "source": []
  }
 ],
 "metadata": {
  "kernelspec": {
   "display_name": "Python 3",
   "language": "python",
   "name": "python3"
  },
  "language_info": {
   "codemirror_mode": {
    "name": "ipython",
    "version": 3
   },
   "file_extension": ".py",
   "mimetype": "text/x-python",
   "name": "python",
   "nbconvert_exporter": "python",
   "pygments_lexer": "ipython3",
   "version": "3.7.4"
  }
 },
 "nbformat": 4,
 "nbformat_minor": 2
}
